# 2025-08-23 异步工作流回归测试验证结果 (第五次测试)

**测试目标文档**：`docs/tests/validation/2025-08-23-postcard-agent-worker.md`
**测试执行时间**：2025-08-23 20:03:00 - 20:20:00
**测试任务ID1**：6ae7e583-aeb9-4d60-8bc7-6a2cdcf31dc0
**测试任务ID2**：8fa1a747-93d2-47d1-a51b-00fa07867d3b

## 测试环境状态

### ✅ 成功项目
1. **服务启动** - 所有预期服务正常启动
   - postgres: Up 43 seconds (healthy)
   - redis: Up 43 seconds (healthy)
   - ai-agent-service: Up 37 seconds
   - postcard-service: Up 37 seconds
   - ai-agent-worker: Up 37 seconds

2. **健康检查** - 所有服务健康检查通过
   ```json
   // postcard-service
   {
     "status": "healthy",
     "service": "postcard-service",
     "environment": "development"
   }
   
   // ai-agent-service
   {
     "message": "AI Agent Service is running",
     "service": "ai-agent-service", 
     "status": "healthy"
   }
   ```

3. **任务创建** - 创建任务接口正常工作
   ```json
   // 任务1
   {
     "task_id": "6ae7e583-aeb9-4d60-8bc7-6a2cdcf31dc0",
     "status": "pending",
     "message": "任务创建成功，正在处理中"
   }
   
   // 任务2
   {
     "task_id": "8fa1a747-93d2-47d1-a51b-00fa07867d3b",
     "status": "pending", 
     "message": "任务创建成功，正在处理中"
   }
   ```

## ❌ 严重问题发现

### 问题1: **CRITICAL** - Worker代码缺失asyncio导入导致全面失败

#### 问题描述
AI Agent Worker在处理任务时立即失败，所有任务状态直接从 `pending` 跳到 `failed`。

#### 错误现象
**Worker 日志**：
```
2025-08-23 12:06:30,595 - TaskConsumer - INFO - 📨 收到任务: 1755950790594-0
2025-08-23 12:06:30,596 - TaskConsumer - INFO - 📋 任务详情: 6ae7e583-aeb9-4d60-8bc7-6a2cdcf31dc0 - 为生日做一张可爱的动态贺卡...
2025-08-23 12:06:30,597 - PostcardWorkflow - ERROR - ❌ 工作流执行失败: 6ae7e583-aeb9-4d60-8bc7-6a2cdcf31dc0 - name 'asyncio' is not defined
2025-08-23 12:06:30,597 - TaskConsumer - ERROR - ❌ 处理任务失败: 1755950790594-0 - name 'asyncio' is not defined
2025-08-23 12:06:30,712 - httpx - INFO - HTTP Request: POST http://postcard-service:8000/api/v1/postcards/status/6ae7e583-aeb9-4d60-8bc7-6a2cdcf31dc0 "HTTP/1.1 200 OK"
2025-08-23 12:06:30,712 - PostcardWorkflow - INFO - ✅ 任务状态更新成功: 6ae7e583-aeb9-4d60-8bc7-6a2cdcf31dc0 -> failed
```

**Postcard Service 日志**：
```
2025-08-23 12:06:30,593 - app.services.queue_service - INFO - ✅ Redis连接成功
2025-08-23 12:06:30,595 - app.services.queue_service - INFO - ✅ 任务发布成功: 6ae7e583-aeb9-4d60-8bc7-6a2cdcf31dc0 - 消息ID: 1755950790594-0
2025-08-23 12:06:30,596 - app.services.postcard_service - INFO - ✅ 任务创建成功: 6ae7e583-aeb9-4d60-8bc7-6a2cdcf31dc0
2025-08-23 12:06:30,709 - app.services.postcard_service - INFO - ✅ 任务状态更新: 6ae7e583-aeb9-4d60-8bc7-6a2cdcf31dc0 -> failed
```

#### 根本原因分析

**源代码定位**：
- **文件路径**：`/app/app/orchestrator/workflow.py` (容器内路径)
- **对应主机路径**：`src/ai-agent-service/app/orchestrator/workflow.py`

**问题代码**：
```python
# workflow.py 文件头部 (行1-6)
import logging
import httpx
import os
from typing import Dict, Any
from datetime import datetime
# ❌ 缺失: import asyncio

# 问题代码位置 (使用了未导入的asyncio)
await asyncio.shield(self.update_task_status(task_id, "processing"))     # 行26
await asyncio.shield(self.save_final_result(task_id, context["results"])) # 行59
await asyncio.shield(self.update_task_status(task_id, "completed"))       # 行60
await asyncio.shield(self.update_task_status(task_id, "failed", str(e)))  # 行67
```

**错误详细分布**：
通过容器内代码搜索确认了asyncio.shield在多处被使用：
```bash
/app/app/orchestrator/workflow.py:26: await asyncio.shield(self.update_task_status(task_id, "processing"))
/app/app/orchestrator/workflow.py:59: await asyncio.shield(self.save_final_result(task_id, context["results"]))
/app/app/orchestrator/workflow.py:60: await asyncio.shield(self.update_task_status(task_id, "completed"))
/app/app/orchestrator/workflow.py:67: await asyncio.shield(self.update_task_status(task_id, "failed", str(e)))
```

#### 任务状态最终结果
```json
// 任务1状态
{
  "task_id": "6ae7e583-aeb9-4d60-8bc7-6a2cdcf31dc0",
  "status": "failed",  // ❌ 直接失败
  "created_at": "2025-08-23T12:06:30.570749Z",
  "updated_at": "2025-08-23T12:06:30.703360Z",
  "completed_at": null,
  "concept": null,      // ❌ 所有结果为空
  "content": null,
  "image_url": null,
  "frontend_code": null,
  "preview_url": null,
  "error_message": "name 'asyncio' is not defined",  // ✅ 错误信息准确
  "retry_count": 1
}

// 任务2状态 (相同错误)
{
  "task_id": "8fa1a747-93d2-47d1-a51b-00fa07867d3b",
  "status": "failed",
  "error_message": "name 'asyncio' is not defined",
  "retry_count": 1
  // ... 其他字段相同
}
```

#### 影响范围
- **🚨 全系统瘫痪**: 所有AI工作流任务都无法执行
- **🚨 前端功能失效**: 无法生成任何明信片内容
- **🚨 业务流程中断**: 从概念生成到前端代码生成全部步骤无法启动

## 测试结果总结

### 🎯 验证目标达成情况

| 验证项目 | 预期结果 | 实际结果 | 状态 |
|---------|---------|---------|------|
| Redis连接 | `✅ Redis连接成功` | ✅ 符合预期 | ✅ |
| 消费者组 | `✅ 消费者组创建成功/已存在` | ✅ 符合预期 | ✅ |
| 收到任务 | `📨 收到任务: ...` | ✅ 符合预期 | ✅ |
| 任务详情 | `📋 任务详情: ...` | ✅ 符合预期 | ✅ |
| 状态转换 | `pending` → `processing` → `completed` | ❌ `pending` → `failed` | ❌ |

### 📊 整体评估

- **连接层面**: ✅ 完全正常 - Redis、数据库连接稳定
- **消息传递**: ✅ 完全正常 - 任务创建和队列投递成功
- **数据处理**: ✅ 完全正常 - Worker能够正确解析和处理任务数据
- **AI工作流**: ❌ **完全失败** - 无法启动任何工作流步骤
- **任务执行**: ❌ **完全失败** - 无法生成任何内容
- **状态管理**: ✅ 部分正常 - 错误状态更新和错误消息记录正常

### 🚨 修复优先级

1. **CRITICAL优先级**: 立即修复 `/app/app/orchestrator/workflow.py` 文件中缺失的 `import asyncio` 导入语句
2. **验证优先级**: 修复后重新验证整个AI工作流是否恢复正常

### 📈 五次测试的回归分析

#### 测试进展时间线
1. **第一次测试**: Pydantic验证错误导致Worker无法处理任务
2. **第二次测试**: Pydantic问题修复，AI工作流完整执行成功
3. **第三次测试**: 继续验证工作流稳定性，发现状态同步问题
4. **第四次测试**: 发现网络异常导致最终状态同步失败
5. **第五次测试**: **代码回退** - 出现严重的导入缺失问题

#### 状况分析
第五次测试结果表明系统出现了严重的代码回退问题。相比前四次测试中Worker能够成功执行整个AI工作流（概念生成、内容生成、图片生成、前端代码生成），第五次测试中Worker连最基本的工作流启动都无法完成。

这说明在服务重建过程中，可能发生了以下情况之一：
1. 源代码被误修改或回退到更早版本
2. Docker镜像构建过程中出现问题
3. 代码同步异常

### 📝 备注

**与前四次测试的对比**：
- **第二至四次测试**: Worker能执行完整AI工作流，只在最后的状态同步步骤有问题
- **第五次测试**: Worker无法启动任何工作流步骤，属于更严重的回退性问题

**建议的修复验证步骤**：
1. 检查源代码 `src/ai-agent-service/app/orchestrator/workflow.py` 是否包含 `import asyncio`
2. 如缺失，添加导入语句：在文件开头添加 `import asyncio`
3. 重建Docker镜像并重新运行验证

**测试环境清理**: 测试完成后已正常关闭所有服务容器。